2022-06-08 14:44:32,744 INFO    MainThread:22924 [internal.py:wandb_internal():90] W&B internal server running at pid: 22924, started at: 2022-06-08 14:44:32.743452
2022-06-08 14:44:32,746 INFO    WriterThread:22924 [datastore.py:open_for_write():75] open: /shared/workspaces/jprofant/GitHub/wespeaker/examples/voxceleb/v2/wandb/run-20220608_144431-shx3m3gu/run-shx3m3gu.wandb
2022-06-08 14:44:32,749 DEBUG   SenderThread:22924 [sender.py:send():232] send: header
2022-06-08 14:44:32,749 DEBUG   SenderThread:22924 [sender.py:send():232] send: run
2022-06-08 14:44:32,769 ERROR   SenderThread:22924 [internal_api.py:execute():143] 409 response executing GraphQL.
2022-06-08 14:44:32,769 ERROR   SenderThread:22924 [internal_api.py:execute():144] {"errors":[{"message":"Error 1062: Duplicate entry 'Jan_DIAR-88-4' for key 'ix_projects_name_entity_id'","path":["upsertBucket"]}],"data":{"upsertBucket":null}}
2022-06-08 14:44:33,747 INFO    HandlerThread:22924 [handler.py:finish():806] shutting down handler
2022-06-08 14:44:33,748 INFO    WriterThread:22924 [datastore.py:close():279] close: /shared/workspaces/jprofant/GitHub/wespeaker/examples/voxceleb/v2/wandb/run-20220608_144431-shx3m3gu/run-shx3m3gu.wandb
2022-06-08 14:44:33,749 ERROR   MainThread:22924 [internal.py:wandb_internal():165] Thread SenderThread:
Traceback (most recent call last):
  File "/shared/workspaces/jprofant/anaconda3/envs/wespeaker/lib/python3.9/site-packages/wandb/apis/normalize.py", line 22, in wrapper
    return func(*args, **kwargs)
  File "/shared/workspaces/jprofant/anaconda3/envs/wespeaker/lib/python3.9/site-packages/wandb/sdk/internal/internal_api.py", line 1319, in upsert_run
    response = self.gql(mutation, variable_values=variable_values, **kwargs)
  File "/shared/workspaces/jprofant/anaconda3/envs/wespeaker/lib/python3.9/site-packages/wandb/sdk/lib/retry.py", line 102, in __call__
    result = self._call_fn(*args, **kwargs)
  File "/shared/workspaces/jprofant/anaconda3/envs/wespeaker/lib/python3.9/site-packages/wandb/sdk/internal/internal_api.py", line 140, in execute
    return self.client.execute(*args, **kwargs)
  File "/shared/workspaces/jprofant/anaconda3/envs/wespeaker/lib/python3.9/site-packages/wandb/vendor/gql-0.2.0/wandb_gql/client.py", line 52, in execute
    result = self._get_result(document, *args, **kwargs)
  File "/shared/workspaces/jprofant/anaconda3/envs/wespeaker/lib/python3.9/site-packages/wandb/vendor/gql-0.2.0/wandb_gql/client.py", line 60, in _get_result
    return self.transport.execute(document, *args, **kwargs)
  File "/shared/workspaces/jprofant/anaconda3/envs/wespeaker/lib/python3.9/site-packages/wandb/vendor/gql-0.2.0/wandb_gql/transport/requests.py", line 39, in execute
    request.raise_for_status()
  File "/shared/workspaces/jprofant/anaconda3/envs/wespeaker/lib/python3.9/site-packages/requests/models.py", line 960, in raise_for_status
    raise HTTPError(http_error_msg, response=self)
requests.exceptions.HTTPError: 409 Client Error: Conflict for url: http://wandb.speech-rnd.internal/graphql

During handling of the above exception, another exception occurred:

Traceback (most recent call last):
  File "/shared/workspaces/jprofant/anaconda3/envs/wespeaker/lib/python3.9/site-packages/wandb/sdk/internal/internal_util.py", line 51, in run
    self._run()
  File "/shared/workspaces/jprofant/anaconda3/envs/wespeaker/lib/python3.9/site-packages/wandb/sdk/internal/internal_util.py", line 102, in _run
    self._process(record)
  File "/shared/workspaces/jprofant/anaconda3/envs/wespeaker/lib/python3.9/site-packages/wandb/sdk/internal/internal.py", line 310, in _process
    self._sm.send(record)
  File "/shared/workspaces/jprofant/anaconda3/envs/wespeaker/lib/python3.9/site-packages/wandb/sdk/internal/sender.py", line 234, in send
    send_handler(record)
  File "/shared/workspaces/jprofant/anaconda3/envs/wespeaker/lib/python3.9/site-packages/wandb/sdk/internal/sender.py", line 692, in send_run
    self._init_run(run, config_value_dict)
  File "/shared/workspaces/jprofant/anaconda3/envs/wespeaker/lib/python3.9/site-packages/wandb/sdk/internal/sender.py", line 716, in _init_run
    server_run, inserted = self._api.upsert_run(
  File "/shared/workspaces/jprofant/anaconda3/envs/wespeaker/lib/python3.9/site-packages/wandb/apis/normalize.py", line 24, in wrapper
    raise CommError(err.response, err)
wandb.errors.CommError: <Response [409]>
2022-06-08 14:44:35,768 INFO    MainThread:22924 [internal.py:handle_exit():80] Internal process exited
